<mujoco>
  <worldbody>
    <light name="top" pos="0 0 1"/>
    
    <!-- Base link (parent) -->
    <body name="base_link" pos="0 0 0">
      <!-- <joint name="base_joint" type="free"/> -->
      <!-- <geom name="base" type="cylinder" size=".1 .05" rgba="0.5 0.5 0.5 1"/> -->
      
      <!-- First link -->
      <body name="link_1" pos="0 0 0.1">
        <joint name="joint_1" type="hinge" axis="1 1 0" pos="0 0 -0.1" damping="0.5"/>
        <geom name="cylinder_1" type="cylinder" size=".05 .3" rgba="1 0 0 1" euler="35 43 0"/>
        <!-- Second link -->
        <body name="link_2" pos="0 0 0.6">
          <joint name="joint_2" type="hinge" axis="0 1 0" pos="0 0 -0.3" damping="0.5"/>
          <geom name="cylinder_2" type="cylinder" size=".05 .3" rgba="1 0 0 1"/>
        </body>
      </body>
    </body>
    
  </worldbody>
</mujoco>